<?xml version="1.0" encoding="UTF-8"?>
<sdf version='1.9'>
    <model name='pegasus'>
        <pose>0 0 0 0 0 0</pose>
        <self_collide>false</self_collide>
        <static>false</static>

        <!-- Base Link definition -->
        <link name="base_link">
            <inertial>
                <mass>1.5</mass>
                <inertia>
                    <ixx>0.029125</ixx>
                    <ixy>0</ixy>
                    <ixz>0</ixz>
                    <iyy>0.029125</iyy>
                    <iyz>0</iyz>
                    <izz>0.055225</izz>
                </inertia>
            </inertial>
            <gravity>true</gravity>
            <velocity_decay />

            <!-- Visual and Collision -->
            <collision name='base_link_inertia_collision'>
                <pose>0 0 0.04 0 0 0</pose>
                <geometry>
                    <box>
                        <size>0.31 0.39 0.095</size>
                    </box>
                </geometry>
                <surface>
                    <contact>
                        <ode>
                            <min_depth>0.001</min_depth>
                            <max_vel>0</max_vel>
                        </ode>
                    </contact>
                    <friction>
                        <ode />
                    </friction>
                </surface>
            </collision>

            <visual name='base_link_inertia_visual'>
                <pose>0 0 0 0 0 -1.5707963268</pose>
                <geometry>
                    <mesh>
                        <scale>1 1 1</scale>
                        <uri>model://pegasus/meshes/pegasus.dae</uri>
                    </mesh>
                </geometry>
            </visual>

            <!-- Sensors -->
            <!-- Air Pressure Sensor -->
            <sensor name="air_pressure_sensor" type="air_pressure">
                <always_on>1</always_on>
                <update_rate>50</update_rate>
                <air_pressure>
                    <!-- Noise modeled after BMP390 -->
                    <pressure>
                        <noise type="gaussian">
                            <mean>0</mean>
                            <stddev>3</stddev>
                        </noise>
                    </pressure>
                </air_pressure>
            </sensor>

            <!-- Magnetometer-->
            <sensor name="magnetometer_sensor" type="magnetometer">
                <always_on>1</always_on>
                <update_rate>100</update_rate>
                <magnetometer>
                    <!-- TODO: update to fix units and coordinate system when we move past Harmonic -->
                    <!-- See https://github.com/gazebosim/gz-sim/pull/2460 -->
                    <!-- 3mgauss RMS: NOTE: noise is in tesla but sensor reports data in gauss -->
                    <!-- Noise modeled after IIS2MDC -->
                    <x>
                        <noise type="gaussian">
                            <stddev>0.0001</stddev>
                        </noise>
                    </x>
                    <y>
                        <noise type="gaussian">
                            <stddev>0.0001</stddev>
                        </noise>
                    </y>
                    <z>
                        <noise type="gaussian">
                            <stddev>0.0001</stddev>
                        </noise>
                    </z>
                </magnetometer>
            </sensor>

            <!-- IMU sensor -->
            <sensor name="imu_sensor" type="imu">
                <always_on>1</always_on>
                <update_rate>250</update_rate>
                <imu>
                    <angular_velocity>
                        <!-- Noise modeled after IIM42653 -->
                        <!-- 0.05 deg/s converted to rad/s -->
                        <x>
                            <noise type="gaussian">
                                <mean>0.0</mean>
                                <stddev>0.0008726646</stddev>
                            </noise>
                        </x>
                        <y>
                            <noise type="gaussian">
                                <mean>0.0</mean>
                                <stddev>0.0008726646</stddev>
                            </noise>
                        </y>
                        <z>
                            <noise type="gaussian">
                                <mean>0.0</mean>
                                <stddev>0.0008726646</stddev>
                            </noise>
                        </z>
                    </angular_velocity>
                    <linear_acceleration>
                        <!-- Noise modeled after IIM42653 -->
                        <!-- X & Y axis: 0.65 mg-rms converted to m/ss -->
                        <x>
                            <noise type="gaussian">
                                <mean>0.0</mean>
                                <stddev>0.00637</stddev>
                            </noise>
                        </x>
                        <y>
                            <noise type="gaussian">
                                <mean>0.0</mean>
                                <stddev>0.00637</stddev>
                            </noise>
                        </y>
                        <!-- Z axis: 0.70 mg-rms converted to m/ss-->
                        <z>
                            <noise type="gaussian">
                                <mean>0.0</mean>
                                <stddev>0.00686</stddev>
                            </noise>
                        </z>
                    </linear_acceleration>
                </imu>
            </sensor>

            <!-- GPS sensor -->
            <sensor name="navsat_sensor" type="navsat">
                <always_on>1</always_on>
                <update_rate>30</update_rate>
            </sensor>

            <!-- Realsense Camera -->
            <sensor name="realsense_d435i" type="rgbd_camera">
                <pose>0.15 0 0 0 0 0</pose>
                <update_rate>60</update_rate>
                <camera name="camera">
                    <horizontal_fov>1.0472</horizontal_fov>
                    <lens>
                        <intrinsics>
                            <!-- fx = fy = width / ( 2 * tan (hfov / 2 ) ) -->
                            <fx>554.25469</fx>
                            <fy>554.25469</fy>
                            <!-- cx = ( width + 1 ) / 2 -->
                            <cx>320.5</cx>
                            <!-- cy = ( height + 1 ) / 2 -->
                            <cy>240.5</cy>
                            <s>0</s>
                        </intrinsics>
                    </lens>
                    <distortion>
                        <k1>0.0</k1>
                        <k2>0.0</k2>
                        <k3>0.0</k3>
                        <p1>0.0</p1>
                        <p2>0.0</p2>
                        <center>0.5 0.5</center>
                    </distortion>
                    <image>
                        <width>640</width>
                        <height>480</height>
                        <format>R8G8B8</format>
                    </image>
                    <clip>
                        <near>0.01</near>
                        <far>300</far>
                    </clip>
                    <depth_camera>
                        <clip>
                            <near>0.1</near>
                            <far>10</far>
                        </clip>
                    </depth_camera>
                    <noise>
                        <type>gaussian</type>
                        <mean>0</mean>
                        <stddev>0.007</stddev>
                    </noise>
                </camera>
            </sensor>

            <!-- Monocular downward-facing camera sensor -->
            <sensor name="downward_camera" type="camera">
                <pose>0.10 0 0 0 1.5707963268 0</pose>
                <update_rate>60</update_rate>
                <camera name="downward_camera">
                    <horizontal_fov>1.0472</horizontal_fov>
                    <lens>
                        <intrinsics>
                            <fx>554.25469</fx>
                            <fy>554.25469</fy>
                            <cx>320.5</cx>
                            <cy>240.5</cy>
                            <s>0</s>
                        </intrinsics>
                    </lens>
                    <distortion>
                        <k1>0.0</k1>
                        <k2>0.0</k2>
                        <k3>0.0</k3>
                        <p1>0.0</p1>
                        <p2>0.0</p2>
                        <center>0.5 0.5</center>
                    </distortion>
                    <image>
                        <width>640</width>
                        <height>480</height>
                        <format>R8G8B8</format>
                    </image>
                    <clip>
                        <near>0.01</near>
                        <far>300</far>
                    </clip>
                    <noise>
                        <type>gaussian</type>
                        <mean>0</mean>
                        <stddev>0.007</stddev>
                    </noise>
                </camera>
            </sensor>
        </link>


        <!-- ROTORS -->
        <!-- ROTOR 0 -->
        <link name='rotor_0'>
            <pose>0.074 -0.113 0.037 0 0 0</pose>
            <inertial>
                <pose>0 0 0 0 0 0</pose>
                <mass>0.005</mass>
                <inertia>
                    <ixx>9.75e-07</ixx>
                    <ixy>0</ixy>
                    <ixz>0</ixz>
                    <iyy>0.000273104</iyy>
                    <iyz>0</iyz>
                    <izz>0.000274004</izz>
                </inertia>
            </inertial>
            <visual name='rotor_0_visual'>
                <pose>0 0 0 0 0 0</pose>
                <geometry>
                    <mesh>
                        <scale>0.5 0.5 0.5</scale>
                        <uri>model://pegasus/meshes/pegasus_prop_cw.dae</uri>
                    </mesh>
                </geometry>
                <material>
                    <ambient>0.175 0.175 0.175 1</ambient>
                    <diffuse>0.175 0.175 0.175 1</diffuse>
                    <specular>0.1 0.1 0.1 1</specular>
                </material>
            </visual>
            <gravity>1</gravity>
            <velocity_decay />
        </link>
        <joint name='rotor_0_joint' type='revolute'>
            <child>rotor_0</child>
            <parent>base_link</parent>
            <axis>
                <xyz>0 0 1</xyz>
                <limit>
                    <lower>-1e+16</lower>
                    <upper>1e+16</upper>
                </limit>
                <dynamics>
                    <spring_reference>0</spring_reference>
                    <spring_stiffness>0</spring_stiffness>
                </dynamics>
            </axis>
        </joint>

        <!-- ROTOR 1 -->
        <link name='rotor_1'>
            <pose>-0.074 0.113 0.037 0 0 0</pose>
            <inertial>
                <pose>0 0 0 0 0 0</pose>
                <mass>0.005</mass>
                <inertia>
                    <ixx>9.75e-07</ixx>
                    <ixy>0</ixy>
                    <ixz>0</ixz>
                    <iyy>0.000273104</iyy>
                    <iyz>0</iyz>
                    <izz>0.000274004</izz>
                </inertia>
            </inertial>
            <visual name='rotor_1_visual'>
                <pose>0 0 0 0 0 0</pose>
                <geometry>
                    <mesh>
                        <scale>0.5 0.5 0.5</scale>
                        <uri>model://pegasus/meshes/pegasus_prop_cw.dae</uri>
                    </mesh>
                </geometry>
                <material>
                    <ambient>0.175 0.175 0.175 1</ambient>
                    <diffuse>0.175 0.175 0.175 1</diffuse>
                    <specular>0.1 0.1 0.1 1</specular>
                </material>
            </visual>
            <gravity>1</gravity>
            <velocity_decay />
        </link>
        <joint name='rotor_1_joint' type='revolute'>
            <child>rotor_1</child>
            <parent>base_link</parent>
            <axis>
                <xyz>0 0 1</xyz>
                <limit>
                    <lower>-1e+16</lower>
                    <upper>1e+16</upper>
                </limit>
                <dynamics>
                    <spring_reference>0</spring_reference>
                    <spring_stiffness>0</spring_stiffness>
                </dynamics>
            </axis>
        </joint>

        <!-- ROTOR 2 -->
        <link name='rotor_2'>
            <pose>0.074 0.113 0.037 0 0 0</pose>
            <inertial>
                <pose>0 0 0 0 0 0</pose>
                <mass>0.005</mass>
                <inertia>
                    <ixx>9.75e-07</ixx>
                    <ixy>0</ixy>
                    <ixz>0</ixz>
                    <iyy>0.000273104</iyy>
                    <iyz>0</iyz>
                    <izz>0.000274004</izz>
                </inertia>
            </inertial>
            <visual name='rotor_2_visual'>
                <pose>0 0 0 0 0 0</pose>
                <geometry>
                    <mesh>
                        <scale>0.5 0.5 0.5</scale>
                        <uri>model://pegasus/meshes/pegasus_prop_cw.dae</uri>
                    </mesh>
                </geometry>
                <material>
                    <ambient>0.175 0.175 0.175 1</ambient>
                    <diffuse>0.175 0.175 0.175 1</diffuse>
                    <specular>0.1 0.1 0.1 1</specular>
                </material>
            </visual>
            <gravity>1</gravity>
            <velocity_decay />
        </link>
        <joint name='rotor_2_joint' type='revolute'>
            <child>rotor_2</child>
            <parent>base_link</parent>
            <axis>
                <xyz>0 0 1</xyz>
                <limit>
                    <lower>-1e+16</lower>
                    <upper>1e+16</upper>
                </limit>
                <dynamics>
                    <spring_reference>0</spring_reference>
                    <spring_stiffness>0</spring_stiffness>
                </dynamics>
            </axis>
        </joint>

        <!-- ROTOR 3 -->
        <link name='rotor_3'>
            <pose>-0.074 -0.113 0.037 0 0 0</pose>
            <inertial>
                <pose>0 0 0 0 0 0</pose>
                <mass>0.005</mass>
                <inertia>
                    <ixx>9.75e-07</ixx>
                    <ixy>0</ixy>
                    <ixz>0</ixz>
                    <iyy>0.000273104</iyy>
                    <iyz>0</iyz>
                    <izz>0.000274004</izz>
                </inertia>
            </inertial>
            <visual name='rotor_3_visual'>
                <pose>0 0 0 0 0 0</pose>
                <geometry>
                    <mesh>
                        <scale>0.5 0.5 0.5</scale>
                        <uri>model://pegasus/meshes/pegasus_prop_cw.dae</uri>
                    </mesh>
                </geometry>
                <material>
                    <ambient>0.175 0.175 0.175 1</ambient>
                    <diffuse>0.175 0.175 0.175 1</diffuse>
                    <specular>0.1 0.1 0.1 1</specular>
                </material>
            </visual>
            <gravity>1</gravity>
            <velocity_decay />
        </link>
        <joint name='rotor_3_joint' type='revolute'>
            <child>rotor_3</child>
            <parent>base_link</parent>
            <axis>
                <xyz>0 0 1</xyz>
                <limit>
                    <lower>-1e+16</lower>
                    <upper>1e+16</upper>
                </limit>
                <dynamics>
                    <spring_reference>0</spring_reference>
                    <spring_stiffness>0</spring_stiffness>
                </dynamics>
            </axis>
        </joint>

        <!-- PLUGINS -->

        <!-- Motor 0 -->
        <plugin filename="gz-sim-multicopter-motor-model-system"
            name="gz::sim::systems::MulticopterMotorModel">
            <jointName>rotor_0_joint</jointName>
            <linkName>rotor_0</linkName>
            <turningDirection>ccw</turningDirection>
            <timeConstantUp>0.0125</timeConstantUp>
            <timeConstantDown>0.025</timeConstantDown>
            <maxRotVelocity>1100</maxRotVelocity>
            <motorConstant>8.54858e-06</motorConstant>
            <momentConstant>0.06</momentConstant>
            <commandSubTopic>command/motor_speed</commandSubTopic>
            <motorNumber>0</motorNumber>
            <rotorDragCoefficient>3.06428e-04</rotorDragCoefficient>
            <rollingMomentCoefficient>1e-06</rollingMomentCoefficient>
            <rotorVelocitySlowdownSim>10</rotorVelocitySlowdownSim>
            <motorType>velocity</motorType>
        </plugin>

        <!-- Motor 1 -->
        <plugin filename="gz-sim-multicopter-motor-model-system"
            name="gz::sim::systems::MulticopterMotorModel">
            <jointName>rotor_1_joint</jointName>
            <linkName>rotor_1</linkName>
            <turningDirection>ccw</turningDirection>
            <timeConstantUp>0.0125</timeConstantUp>
            <timeConstantDown>0.025</timeConstantDown>
            <maxRotVelocity>1100</maxRotVelocity>
            <motorConstant>8.54858e-06</motorConstant>
            <momentConstant>0.06</momentConstant>
            <commandSubTopic>command/motor_speed</commandSubTopic>
            <motorNumber>1</motorNumber>
            <rotorDragCoefficient>3.06428e-04</rotorDragCoefficient>
            <rollingMomentCoefficient>1e-06</rollingMomentCoefficient>
            <rotorVelocitySlowdownSim>10</rotorVelocitySlowdownSim>
            <motorType>velocity</motorType>
        </plugin>

        <!-- Motor 2 -->
        <plugin filename="gz-sim-multicopter-motor-model-system"
            name="gz::sim::systems::MulticopterMotorModel">
            <jointName>rotor_2_joint</jointName>
            <linkName>rotor_2</linkName>
            <turningDirection>cw</turningDirection>
            <timeConstantUp>0.0125</timeConstantUp>
            <timeConstantDown>0.025</timeConstantDown>
            <maxRotVelocity>1100</maxRotVelocity>
            <motorConstant>8.54858e-06</motorConstant>
            <momentConstant>0.06</momentConstant>
            <commandSubTopic>command/motor_speed</commandSubTopic>
            <motorNumber>2</motorNumber>
            <rotorDragCoefficient>3.06428e-04</rotorDragCoefficient>
            <rollingMomentCoefficient>1e-06</rollingMomentCoefficient>
            <rotorVelocitySlowdownSim>10</rotorVelocitySlowdownSim>
            <motorType>velocity</motorType>
        </plugin>

        <!-- Motor 3 -->
        <plugin filename="gz-sim-multicopter-motor-model-system"
            name="gz::sim::systems::MulticopterMotorModel">
            <jointName>rotor_3_joint</jointName>
            <linkName>rotor_3</linkName>
            <turningDirection>cw</turningDirection>
            <timeConstantUp>0.0125</timeConstantUp>
            <timeConstantDown>0.025</timeConstantDown>
            <maxRotVelocity>1100</maxRotVelocity>
            <motorConstant>8.54858e-06</motorConstant>
            <momentConstant>0.06</momentConstant>
            <commandSubTopic>command/motor_speed</commandSubTopic>
            <motorNumber>3</motorNumber>
            <rotorDragCoefficient>3.06428e-04</rotorDragCoefficient>
            <rollingMomentCoefficient>1e-06</rollingMomentCoefficient>
            <rotorVelocitySlowdownSim>10</rotorVelocitySlowdownSim>
            <motorType>velocity</motorType>
        </plugin>
    </model>
</sdf>